Workbook

Sheet Certification
B1: Foundational Data Product™ Progressive Certification
B2: Foundeon
B3: © 2026 Anna Jibgashvili | Foundeon | www.foundeon.com | foundationaldataproducts.com
B5: Product name
B6: Product ID
B7: Assessed by (role)
B8: Assessment date
B10: Instructions: Score each criterion from 0 to 100 against current evidence, not intent. 0 means no evidence; 100 means fully evidenced and monitored. Enter scores in the blue column. Weighted scores, dimension percentages, the certification percentage and the certification level calculate automatically. Complete the condition questions below the table.
B12: Dimension | C12: Criterion | D12: Score (0-100) | E12: Weight | F12: Weighted Score | G12: Gap Analysis
B13: Data Quality | C13: Critical data elements meet completeness and correctness targets at the source and in the product. | E13: 0.05 | F13: =IF(ISBLANK(D13),"",D13*E13) | G13: =IF(ISBLANK(D13),"",IF(D13>=80,"Strong",IF(D13>=60,"Building","Needs Work")))
C14: Data arrives within each source's contracted refresh frequency. | E14: 0.05 | F14: =IF(ISBLANK(D14),"",D14*E14) | G14: =IF(ISBLANK(D14),"",IF(D14>=80,"Strong",IF(D14>=60,"Building","Needs Work")))
C15: Duplicates and cross-source conflicts are identified and resolved against a declared authoritative source per attribute. | E15: 0.05 | F15: =IF(ISBLANK(D15),"",D15*E15) | G15: =IF(ISBLANK(D15),"",IF(D15>=80,"Strong",IF(D15>=60,"Building","Needs Work")))
B16: Data Quality subtotal | C16: Dimension percentage → | D16: =IF(COUNT(D13:D15)=0,"",SUM(F13:F15)/SUM(E13:E15)) | E16: =SUM(E13:E15) | F16: =IF(COUNT(D13:D15)=0,"",SUM(F13:F15)) | G16: =IF(D16="","","of "&TEXT(E16*100,"0")&" points")
B18: Semantic Coherence | C18: Every critical data element carries an approved business definition. | E18: 0.05 | F18: =IF(ISBLANK(D18),"",D18*E18) | G18: =IF(ISBLANK(D18),"",IF(D18>=80,"Strong",IF(D18>=60,"Building","Needs Work")))
C19: Definitions are reconciled with the enterprise-level meaning used by other products, with no open conflicts. | E19: 0.05 | F19: =IF(ISBLANK(D19),"",D19*E19) | G19: =IF(ISBLANK(D19),"",IF(D19>=80,"Strong",IF(D19>=60,"Building","Needs Work")))
C20: Each concept resolves to a single column definition and name across the sources that feed the product. | E20: 0.05 | F20: =IF(ISBLANK(D20),"",D20*E20) | G20: =IF(ISBLANK(D20),"",IF(D20>=80,"Strong",IF(D20>=60,"Building","Needs Work")))
B21: Semantic Coherence subtotal | C21: Dimension percentage → | D21: =IF(COUNT(D18:D20)=0,"",SUM(F18:F20)/SUM(E18:E20)) | E21: =SUM(E18:E20) | F21: =IF(COUNT(D18:D20)=0,"",SUM(F18:F20)) | G21: =IF(D21="","","of "&TEXT(E21*100,"0")&" points")
B23: Metadata Completeness | C23: The product contract states purpose, scope, ownership, permitted use and prohibited use. | E23: 0.0334 | F23: =IF(ISBLANK(D23),"",D23*E23) | G23: =IF(ISBLANK(D23),"",IF(D23>=80,"Strong",IF(D23>=60,"Building","Needs Work")))
C24: Every field carries a description, data type and classification. | E24: 0.0333 | F24: =IF(ISBLANK(D24),"",D24*E24) | G24: =IF(ISBLANK(D24),"",IF(D24>=80,"Strong",IF(D24>=60,"Building","Needs Work")))
C25: The product is registered in the enterprise catalog with its passport. | E25: 0.0333 | F25: =IF(ISBLANK(D25),"",D25*E25) | G25: =IF(ISBLANK(D25),"",IF(D25>=80,"Strong",IF(D25>=60,"Building","Needs Work")))
B26: Metadata Completeness subtotal | C26: Dimension percentage → | D26: =IF(COUNT(D23:D25)=0,"",SUM(F23:F25)/SUM(E23:E25)) | E26: =SUM(E23:E25) | F26: =IF(COUNT(D23:D25)=0,"",SUM(F23:F25)) | G26: =IF(D26="","","of "&TEXT(E26*100,"0")&" points")
B28: Lineage Transparency | C28: The origin of every attribute is documented. | E28: 0.05 | F28: =IF(ISBLANK(D28),"",D28*E28) | G28: =IF(ISBLANK(D28),"",IF(D28>=80,"Strong",IF(D28>=60,"Building","Needs Work")))
C29: Transformations from source to product are documented and versioned. | E29: 0.05 | F29: =IF(ISBLANK(D29),"",D29*E29) | G29: =IF(ISBLANK(D29),"",IF(D29>=80,"Strong",IF(D29>=60,"Building","Needs Work")))
C30: Lineage is traceable through to consumption and has been audited. | E30: 0.05 | F30: =IF(ISBLANK(D30),"",D30*E30) | G30: =IF(ISBLANK(D30),"",IF(D30>=80,"Strong",IF(D30>=60,"Building","Needs Work")))
B31: Lineage Transparency subtotal | C31: Dimension percentage → | D31: =IF(COUNT(D28:D30)=0,"",SUM(F28:F30)/SUM(E28:E30)) | E31: =SUM(E28:E30) | F31: =IF(COUNT(D28:D30)=0,"",SUM(F28:F30)) | G31: =IF(D31="","","of "&TEXT(E31*100,"0")&" points")
B33: Security and Compliance | C33: Access controls enforce the permitted uses stated in the contract. | E33: 0.05 | F33: =IF(ISBLANK(D33),"",D33*E33) | G33: =IF(ISBLANK(D33),"",IF(D33>=80,"Strong",IF(D33>=60,"Building","Needs Work")))
C34: Sensitive data is masked, encrypted or minimized as policy requires. | E34: 0.05 | F34: =IF(ISBLANK(D34),"",D34*E34) | G34: =IF(ISBLANK(D34),"",IF(D34>=80,"Strong",IF(D34>=60,"Building","Needs Work")))
C35: Applicable regulatory obligations are mapped to the product and evidenced. | E35: 0.05 | F35: =IF(ISBLANK(D35),"",D35*E35) | G35: =IF(ISBLANK(D35),"",IF(D35>=80,"Strong",IF(D35>=60,"Building","Needs Work")))
B36: Security and Compliance subtotal | C36: Dimension percentage → | D36: =IF(COUNT(D33:D35)=0,"",SUM(F33:F35)/SUM(E33:E35)) | E36: =SUM(E33:E35) | F36: =IF(COUNT(D33:D35)=0,"",SUM(F33:F35)) | G36: =IF(D36="","","of "&TEXT(E36*100,"0")&" points")
B38: Governance | C38: A named owner and steward, held as roles, hold explicit decision rights over the product. | E38: 0.0334 | F38: =IF(ISBLANK(D38),"",D38*E38) | G38: =IF(ISBLANK(D38),"",IF(D38>=80,"Strong",IF(D38>=60,"Building","Needs Work")))
C39: Changes to meaning, permitted use or authority follow approved change control, with each approval recorded. | E39: 0.0333 | F39: =IF(ISBLANK(D39),"",D39*E39) | G39: =IF(ISBLANK(D39),"",IF(D39>=80,"Strong",IF(D39>=60,"Building","Needs Work")))
C40: Incident and escalation paths are defined and have been tested. | E40: 0.0333 | F40: =IF(ISBLANK(D40),"",D40*E40) | G40: =IF(ISBLANK(D40),"",IF(D40>=80,"Strong",IF(D40>=60,"Building","Needs Work")))
B41: Governance subtotal | C41: Dimension percentage → | D41: =IF(COUNT(D38:D40)=0,"",SUM(F38:F40)/SUM(E38:E40)) | E41: =SUM(E38:E40) | F41: =IF(COUNT(D38:D40)=0,"",SUM(F38:F40)) | G41: =IF(D41="","","of "&TEXT(E41*100,"0")&" points")
B43: Performance | C43: Freshness and latency meet the service levels in the contract. | E43: 0.0267 | F43: =IF(ISBLANK(D43),"",D43*E43) | G43: =IF(ISBLANK(D43),"",IF(D43>=80,"Strong",IF(D43>=60,"Building","Needs Work")))
C44: Availability meets its target. | E44: 0.0267 | F44: =IF(ISBLANK(D44),"",D44*E44) | G44: =IF(ISBLANK(D44),"",IF(D44>=80,"Strong",IF(D44>=60,"Building","Needs Work")))
C45: Monitoring and alerting cover failures, quality breaches and service-level breaches. | E45: 0.0266 | F45: =IF(ISBLANK(D45),"",D45*E45) | G45: =IF(ISBLANK(D45),"",IF(D45>=80,"Strong",IF(D45>=60,"Building","Needs Work")))
B46: Performance subtotal | C46: Dimension percentage → | D46: =IF(COUNT(D43:D45)=0,"",SUM(F43:F45)/SUM(E43:E45)) | E46: =SUM(E43:E45) | F46: =IF(COUNT(D43:D45)=0,"",SUM(F43:F45)) | G46: =IF(D46="","","of "&TEXT(E46*100,"0")&" points")
B48: Accessibility and Interoperability | C48: Governed access methods are documented and tested. | E48: 0.04 | F48: =IF(ISBLANK(D48),"",D48*E48) | G48: =IF(ISBLANK(D48),"",IF(D48>=80,"Strong",IF(D48>=60,"Building","Needs Work")))
C49: People and systems, including AI agents, can consume the product through a machine-readable contract and standard interfaces. | E49: 0.04 | F49: =IF(ISBLANK(D49),"",D49*E49) | G49: =IF(ISBLANK(D49),"",IF(D49>=80,"Strong",IF(D49>=60,"Building","Needs Work")))
C50: The product joins to other Foundational Data Products™ through shared, governed identifiers. | E50: 0.04 | F50: =IF(ISBLANK(D50),"",D50*E50) | G50: =IF(ISBLANK(D50),"",IF(D50>=80,"Strong",IF(D50>=60,"Building","Needs Work")))
...

Sheet Trust Profile
B1: Trust Profile
B2: What a consumer or agent sees when it opens the product's passport.
B3: © 2026 Anna Jibgashvili | Foundeon | www.foundeon.com | foundationaldataproducts.com
B5: Product | C5: =Certification!C5
B6: Certification percentage | C6: =Certification!F53
B7: Certification level | C7: =Certification!C71
B8: Certification seal | C8: =Certification!C72
B10: Dimension | C10: Weight | D10: Dimension % | E10: Trust signal | F10: Floor
B11: Data Quality | C11: 0.15 | D11: =Certification!D16 | E11: =IF(D11="","",IF(D11>=80,"Strong",IF(D11>=60,"Building","Needs work"))) | F11: None
B12: Semantic Coherence | C12: 0.15 | D12: =Certification!D21 | E12: =IF(D12="","",IF(D12>=80,"Strong",IF(D12>=60,"Building","Needs work"))) | F12: 70 Gold
B13: Metadata Completeness | C13: 0.1 | D13: =Certification!D26 | E13: =IF(D13="","",IF(D13>=80,"Strong",IF(D13>=60,"Building","Needs work"))) | F13: None
B14: Lineage Transparency | C14: 0.15 | D14: =Certification!D31 | E14: =IF(D14="","",IF(D14>=80,"Strong",IF(D14>=60,"Building","Needs work"))) | F14: 70 Gold
B15: Security and Compliance | C15: 0.15 | D15: =Certification!D36 | E15: =IF(D15="","",IF(D15>=80,"Strong",IF(D15>=60,"Building","Needs work"))) | F15: 60 Silver · 80 Gold
B16: Governance | C16: 0.1 | D16: =Certification!D41 | E16: =IF(D16="","",IF(D16>=80,"Strong",IF(D16>=60,"Building","Needs work"))) | F16: 70 Gold
B17: Performance | C17: 0.08 | D17: =Certification!D46 | E17: =IF(D17="","",IF(D17>=80,"Strong",IF(D17>=60,"Building","Needs work"))) | F17: None
B18: Accessibility and Interoperability | C18: 0.12 | D18: =Certification!D51 | E18: =IF(D18="","",IF(D18>=80,"Strong",IF(D18>=60,"Building","Needs work"))) | F18: None
B20: Trust travels with the data. The level summarizes the product; the dimension percentages tell each consumer whether it can rely on the product for its own purpose.
B22: © 2026 Anna Jibgashvili | Foundeon | www.foundeon.com | foundationaldataproducts.com

Sheet Consumer Fit
B1: Consumer Fit Check
B2: Whether this product can be relied on for a specific purpose, below Gold or at Gold.
B3: For each consumer, such as an AI agent, enter the minimum dimension percentage its purpose needs. Leave a cell blank where a dimension does not affect that purpose. The check compares the requirement with the product's trust profile.
B5: Consumer | C5: Product % | D5: Consumer 1 | F5: Consumer 2 | H5: Consumer 3
B6: Purpose
D7: Minimum needed | E7: Result | F7: Minimum needed | G7: Result | H7: Minimum needed | I7: Result
B8: Data Quality | C8: =Certification!D16 | E8: =IF(D8="","Not relevant",IF(C8="","",IF(C8>=D8,"Meets","Below"))) | G8: =IF(F8="","Not relevant",IF(C8="","",IF(C8>=F8,"Meets","Below"))) | I8: =IF(H8="","Not relevant",IF(C8="","",IF(C8>=H8,"Meets","Below")))
B9: Semantic Coherence | C9: =Certification!D21 | E9: =IF(D9="","Not relevant",IF(C9="","",IF(C9>=D9,"Meets","Below"))) | G9: =IF(F9="","Not relevant",IF(C9="","",IF(C9>=F9,"Meets","Below"))) | I9: =IF(H9="","Not relevant",IF(C9="","",IF(C9>=H9,"Meets","Below")))
B10: Metadata Completeness | C10: =Certification!D26 | E10: =IF(D10="","Not relevant",IF(C10="","",IF(C10>=D10,"Meets","Below"))) | G10: =IF(F10="","Not relevant",IF(C10="","",IF(C10>=F10,"Meets","Below"))) | I10: =IF(H10="","Not relevant",IF(C10="","",IF(C10>=H10,"Meets","Below")))
B11: Lineage Transparency | C11: =Certification!D31 | E11: =IF(D11="","Not relevant",IF(C11="","",IF(C11>=D11,"Meets","Below"))) | G11: =IF(F11="","Not relevant",IF(C11="","",IF(C11>=F11,"Meets","Below"))) | I11: =IF(H11="","Not relevant",IF(C11="","",IF(C11>=H11,"Meets","Below")))
B12: Security and Compliance | C12: =Certification!D36 | E12: =IF(D12="","Not relevant",IF(C12="","",IF(C12>=D12,"Meets","Below"))) | G12: =IF(F12="","Not relevant",IF(C12="","",IF(C12>=F12,"Meets","Below"))) | I12: =IF(H12="","Not relevant",IF(C12="","",IF(C12>=H12,"Meets","Below")))
B13: Governance | C13: =Certification!D41 | E13: =IF(D13="","Not relevant",IF(C13="","",IF(C13>=D13,"Meets","Below"))) | G13: =IF(F13="","Not relevant",IF(C13="","",IF(C13>=F13,"Meets","Below"))) | I13: =IF(H13="","Not relevant",IF(C13="","",IF(C13>=H13,"Meets","Below")))
B14: Performance | C14: =Certification!D46 | E14: =IF(D14="","Not relevant",IF(C14="","",IF(C14>=D14,"Meets","Below"))) | G14: =IF(F14="","Not relevant",IF(C14="","",IF(C14>=F14,"Meets","Below"))) | I14: =IF(H14="","Not relevant",IF(C14="","",IF(C14>=H14,"Meets","Below")))
B15: Accessibility and Interoperability | C15: =Certification!D51 | E15: =IF(D15="","Not relevant",IF(C15="","",IF(C15>=D15,"Meets","Below"))) | G15: =IF(F15="","Not relevant",IF(C15="","",IF(C15>=F15,"Meets","Below"))) | I15: =IF(H15="","Not relevant",IF(C15="","",IF(C15>=H15,"Meets","Below")))
B16: Fit for this purpose | D16: =IF(COUNTIF(E8:E15,"Below")>0,"Not yet","Yes") | F16: =IF(COUNTIF(G8:G15,"Below")>0,"Not yet","Yes") | H16: =IF(COUNTIF(I8:I15,"Below")>0,"Not yet","Yes")
B18: A consumer's minimums usually come from its own passport or requirements. The product does not need to be Gold for every use.
B20: © 2026 Anna Jibgashvili | Foundeon | www.foundeon.com | foundationaldataproducts.com

Sheet Formula
B2: Weighted Score formula is:
B3: =IF(ISBLANK(D[row]),"",D[row]*E[row])
B5: What it does:
B6: IF(ISBLANK(D[row]),"",...) checks whether the Score cell is blank. If blank, it shows nothing. If not, it calculates the weighted score.
B7: D[row] = Score, 0 to 100
B8: E[row] = Weight of the criterion. Each dimension's weight is split across its three criteria.
B10: Example calculation:
B11: Score = 85, Weight = 0.05 (one of three Data Quality criteria, 15% in total)
B12: Formula: 85 × 0.05 = 4.25 points
B14: Why no multiplier:
B15: Weights add up to 1.0 (100%). Scores run from 0 to 100. A perfect score on every criterion gives 100 × 1.0 = 100.
B17: So:
... B22: © 2026 Anna Jibgashvili | Foundeon | www.foundeon.com | foundationaldataproducts.com
